<?xml version="1.0"?>
<robot name="onshape">
<link name="arctos_base">
<visual>
<origin xyz="0.36446432317721999539 -0.050932388280227801347 0.01278915646413278373" rpy="1.5707963267948970021 -3.5898807087421401208e-32 0" />
<geometry>
<mesh filename="arctos_base.stl"/>
</geometry>
<material name="arctos_base_material">
<color rgba="0.36470588235294115753 0.34901960784313723618 0.34901960784313723618 1.0"/>
</material>
</visual>
<collision>
<origin xyz="0.36446432317721999539 -0.050932388280227801347 0.01278915646413278373" rpy="1.5707963267948970021 -3.5898807087421401208e-32 0" />
<geometry>
<mesh filename="arctos_base.stl"/>
</geometry>
</collision>
<inertial>
<origin xyz="-0.036190959675620582026 0.00020785040026151391235 0.068366067250913500897" rpy="0 0 0"/>
<mass value="1.0413378737551433062" />
<inertia ixx="0.0041148955809766915928" ixy="1.0348039067265013964e-05"  ixz="-0.00024546722757149916101" iyy="0.008014140699617509217" iyz="2.0104548488852764908e-05" izz="0.0091517727045413513332" />
</inertial>
</link>

<link name="arctos_lower">
<visual>
<origin xyz="-0.13500667682278003068 -0.67306761171977191882 0.21711684529782718234" rpy="-1.5707963267948970021 3.3896367021215351014e-32 1.3870680216142022316e-32" />
<geometry>
<mesh filename="arctos_lower.stl"/>
</geometry>
<material name="arctos_lower_material">
<color rgba="0.36470588235294115753 0.34901960784313723618 0.34901960784313723618 1.0"/>
</material>
</visual>
<collision>
<origin xyz="-0.13500667682278003068 -0.67306761171977191882 0.21711684529782718234" rpy="-1.5707963267948970021 3.3896367021215351014e-32 1.3870680216142022316e-32" />
<geometry>
<mesh filename="arctos_lower.stl"/>
</geometry>
</collision>
<inertial>
<origin xyz="0.0047448268972576090885 -0.00075818073811162445524 -0.068542518367652224831" rpy="0 0 0"/>
<mass value="1.4118318629235360184" />
<inertia ixx="0.0099867569287504509568" ixy="-1.6336903968690115241e-05"  ixz="0.00056899988327101063117" iyy="0.0085064618006165087366" iyz="-3.9895527683299233891e-05" izz="0.0074548597601912019658" />
</inertial>
</link>

<link name="arctos_middle">
<visual>
<origin xyz="-0.1558912631663369186 0.37483909607875859349 -0.35099752243260728957" rpy="3.1415926535896896432 2.4650827656672588928e-15 0" />
<geometry>
<mesh filename="arctos_middle.stl"/>
</geometry>
<material name="arctos_middle_material">
<color rgba="0.36470588235294115753 0.34901960784313723618 0.34901960784313723618 1.0"/>
</material>
</visual>
<collision>
<origin xyz="-0.1558912631663369186 0.37483909607875859349 -0.35099752243260728957" rpy="3.1415926535896896432 2.4650827656672588928e-15 0" />
<geometry>
<mesh filename="arctos_middle.stl"/>
</geometry>
</collision>
<inertial>
<origin xyz="-0.0077610876941956175035 -0.097207484813876990359 -0.0021039682733151598981" rpy="0 0 0"/>
<mass value="1.5722421951083009883" />
<inertia ixx="0.021007624959748037036" ixy="-0.00058118807975816475994"  ixz="-2.4174071959998562014e-06" iyy="0.0054104134634057826983" iyz="-0.0003553759374561382754" izz="0.019428304674691285886" />
</inertial>
</link>

<link name="arctos_upper">
<visual>
<origin xyz="0.14541909986832687873 0.6358457520286575626 0.1725104060293389252" rpy="3.1415926535897820138 -1.3127138500943399574e-29 0" />
<geometry>
<mesh filename="arctos_upper.stl"/>
</geometry>
<material name="arctos_upper_material">
<color rgba="0.36470588235294115753 0.34901960784313723618 0.34901960784313723618 1.0"/>
</material>
</visual>
<collision>
<origin xyz="0.14541909986832687873 0.6358457520286575626 0.1725104060293389252" rpy="3.1415926535897820138 -1.3127138500943399574e-29 0" />
<geometry>
<mesh filename="arctos_upper.stl"/>
</geometry>
</collision>
<inertial>
<origin xyz="0.042603881422939582357 -0.01318629926465652788 -0.0044323894721380041606" rpy="0 0 0"/>
<mass value="0.6272436456112834291" />
<inertia ixx="0.001098258435988238961" ixy="0.00034400596114381274283"  ixz="2.6714063061833948304e-05" iyy="0.0023035587444470715171" iyz="8.1998855604538040107e-07" izz="0.0024292434969864782138" />
</inertial>
</link>

<link name="wrist">
<visual>
<origin xyz="-6.4678609350145299661e-05 0.72728002374397204832 0.25480483554865324125" rpy="1.570796326794896558 1.5707963267948734654 0" />
<geometry>
<mesh filename="wrist.stl"/>
</geometry>
<material name="wrist_material">
<color rgba="0.36470588235294115753 0.34901960784313723618 0.34901960784313723618 1.0"/>
</material>
</visual>
<collision>
<origin xyz="-6.4678609350145299661e-05 0.72728002374397204832 0.25480483554865324125" rpy="1.570796326794896558 1.5707963267948734654 0" />
<geometry>
<mesh filename="wrist.stl"/>
</geometry>
</collision>
<inertial>
<origin xyz="0.00032712819674644941659 0.00088618839608645139094 -0.062634235193646026207" rpy="0 0 0"/>
<mass value="0.56700886652075166428" />
<inertia ixx="0.0017224011616626441323" ixy="-3.2378532134891983274e-06"  ixz="2.2423365243662443846e-06" iyy="0.0025275429458428504657" iyz="4.2700358274835239228e-06" izz="0.001648434838453803836" />
</inertial>
</link>

<link name="gripper_assembly_inner">
<visual>
<origin xyz="-0.69122919913551117421 0.89850565816919669704 -0.00030917413090954595778" rpy="1.5707963267948501507 3.0026328645682553997e-14 0" />
<geometry>
<mesh filename="gripper_assembly_inner.stl"/>
</geometry>
<material name="gripper_assembly_inner_material">
<color rgba="0.36470588235294115753 0.34901960784313723618 0.34901960784313723618 1.0"/>
</material>
</visual>
<collision>
<origin xyz="-0.69122919913551117421 0.89850565816919669704 -0.00030917413090954595778" rpy="1.5707963267948501507 3.0026328645682553997e-14 0" />
<geometry>
<mesh filename="gripper_assembly_inner.stl"/>
</geometry>
</collision>
<inertial>
<origin xyz="0.011020965697441820197 0.00094154436931925822307 -1.0948328466343516317e-05" rpy="0 0 0"/>
<mass value="0.19463214953987617584" />
<inertia ixx="0.00019075093016280274" ixy="-2.9969127833516304256e-06"  ixz="1.3261955499520421142e-06" iyy="0.00018053572959174157353" iyz="-7.0780456099494379549e-07" izz="0.00013669039010845556999" />
</inertial>
</link>

<link name="gripper_assembly_outer">
<visual>
<origin xyz="-0.00030917413082717781769 0.72550565816917211848 0.77006421831530924571" rpy="1.570796326794896558 1.5707963267948108488 0" />
<geometry>
<mesh filename="gripper_assembly_outer.stl"/>
</geometry>
<material name="gripper_assembly_outer_material">
<color rgba="0.36470588235294115753 0.34901960784313723618 0.34901960784313723618 1.0"/>
</material>
</visual>
<collision>
<origin xyz="-0.00030917413082717781769 0.72550565816917211848 0.77006421831530924571" rpy="1.570796326794896558 1.5707963267948108488 0" />
<geometry>
<mesh filename="gripper_assembly_outer.stl"/>
</geometry>
</collision>
<inertial>
<origin xyz="0.0023078548156734955688 0.0015298518696794660698 -0.014904895190532396754" rpy="0 0 0"/>
<mass value="0.13208625646334956616" />
<inertia ixx="7.3099317201127627492e-05" ixy="-4.3535423704887063263e-07"  ixz="1.4020744687041522689e-06" iyy="5.3011901725088414982e-05" iyz="2.0558618122064588241e-06" izz="9.2782765523292997159e-05" />
</inertial>
</link>

<link name="left_jaw">
<visual>
<origin xyz="-0.93730780726064277797 0.011449734339888259504 -0.85360877917690336503" rpy="4.7184478546569162829e-16 -4.1633363423443360405e-16 -1.7347234759768067092e-18" />
<geometry>
<mesh filename="left_jaw.stl"/>
</geometry>
<material name="left_jaw_material">
<color rgba="0.36470588235294115753 0.34901960784313723618 0.34901960784313723618 1.0"/>
</material>
</visual>
<collision>
<origin xyz="-0.93730780726064277797 0.011449734339888259504 -0.85360877917690336503" rpy="4.7184478546569162829e-16 -4.1633363423443360405e-16 -1.7347234759768067092e-18" />
<geometry>
<mesh filename="left_jaw.stl"/>
</geometry>
</collision>
<inertial>
<origin xyz="0.0096515875393935468551 0.0085641264668806262039 -0.0093615856526801932702" rpy="0 0 0"/>
<mass value="0.0104625931880081742" />
<inertia ixx="9.2962831781350460697e-07" ixy="-2.4644848607999935056e-07"  ixz="5.5626744662579595247e-08" iyy="1.571823870495268752e-06" iyz="-6.4619821813408840968e-08" izz="1.992768184453007196e-06" />
</inertial>
</link>

<link name="right_jaw">
<visual>
<origin xyz="-0.93738987107128246556 0.0080497863765595645269 0.79405722866396966086" rpy="-3.1415926535897926719 3.747002708109903817e-16 -1.7347234759768074796e-18" />
<geometry>
<mesh filename="right_jaw.stl"/>
</geometry>
<material name="right_jaw_material">
<color rgba="0.36470588235294115753 0.34901960784313723618 0.34901960784313723618 1.0"/>
</material>
</visual>
<collision>
<origin xyz="-0.93738987107128246556 0.0080497863765595645269 0.79405722866396966086" rpy="-3.1415926535897926719 3.747002708109903817e-16 -1.7347234759768074796e-18" />
<geometry>
<mesh filename="right_jaw.stl"/>
</geometry>
</collision>
<inertial>
<origin xyz="0.0098782530285080882848 0.0083977308091668333156 -0.0093704955663523881171" rpy="0 0 0"/>
<mass value="0.010168042155151081618" />
<inertia ixx="8.1863262306155616526e-07" ixy="-1.4294311148962495056e-07"  ixz="5.6910197664185491415e-08" iyy="1.5153751895386130304e-06" iyz="-6.6817746618915091216e-08" izz="1.8599601659645511485e-06" />
</inertial>
</link>


<joint name="outer_inner" type="revolute">
<origin xyz="0.039835445112786860289 -2.2204460492503130808e-15 -3.6776137690708310402e-15" rpy="-1.5707963267949791586 1.3778210289552164092 1.5707963267947004926" />
<parent link="gripper_assembly_inner" />
<child link="gripper_assembly_outer" />
<axis xyz="0 0 1"/>
<limit effort="12" velocity="20" lower="-3.4906585039886590671" upper="3.4906585039886590671"/>
<joint_properties friction="0.0"/>
</joint>

<joint name="inner_wrist" type="revolute">
<origin xyz="0.00021854809329471813761 0.0017743655747750608498 -0.12542436358686440134" rpy="-6.9874661612348195789e-15 1.5707963267948850117 0" />
<parent link="wrist" />
<child link="gripper_assembly_inner" />
<axis xyz="0 0 1"/>
<limit effort="12" velocity="20" lower="-1.6580627893946131568" upper="1.6580627893946131568"/>
<joint_properties friction="0.0"/>
</joint>

<joint name="wrist_upper" type="revolute">
<origin xyz="0.13874345514589062067 -0.021748655380295134343 -0.0054925270810687130268" rpy="-1.5707963267948807928 -1.5245022596773765144 1.5688068046258516475" />
<parent link="arctos_upper" />
<child link="wrist" />
<axis xyz="0 0 1"/>
<limit effort="12" velocity="20" lower="-3.2288591161895094928" upper="3.2288591161895094928"/>
<joint_properties friction="0.0"/>
</joint>

<joint name="upper_middle" type="revolute">
<origin xyz="-0.0013103630346719770308 -0.26100665594985539286 0.0054290868549383020786" rpy="-1.0765344187740975265e-13 8.1164530008389699728e-15 0.0040744247603443310007" />
<parent link="arctos_middle" />
<child link="arctos_upper" />
<axis xyz="0 0 1"/>
<limit effort="12" velocity="20" lower="-1.8325957145940461324" upper="0.87266462599716476678"/>
<joint_properties friction="0.0"/>
</joint>

<joint name="middle_lower" type="revolute">
<origin xyz="0.020885040968205974277 0.00086987140237410553144 -0.15772234492155495778" rpy="1.5707963267950006969 -0.06504782007281141587 1.5951947608009762544e-16" />
<parent link="arctos_lower" />
<child link="arctos_middle" />
<axis xyz="0 0 1"/>
<limit effort="12" velocity="20" lower="-1.3089969389957472057" upper="2.356194490192344837"/>
<joint_properties friction="0.0"/>
</joint>

<joint name="lower_base" type="revolute">
<origin xyz="-0.00052900000000000169109 0 0.12990600176195876703" rpy="-3.1415926535897926719 2.4377752293772548502e-17 1.4977683394279026321e-14" />
<parent link="arctos_base" />
<child link="arctos_lower" />
<axis xyz="0 0 1"/>
<limit effort="12" velocity="20" lower="-6.283185307179586232" upper="6.283185307179586232"/>
<joint_properties friction="0.0"/>
</joint>

<joint name="slide_left" type="prismatic">
<origin xyz="-0.012068082601611365701 -0.029103138881718670916 -0.040243588945377273269" rpy="1.5707963267948992225 1.5707963267948146235 0" />
<parent link="gripper_assembly_outer" />
<child link="left_jaw" />
<axis xyz="0 0 1"/>
<limit effort="12" velocity="20" lower="-0.015" upper="0.0"/>
<joint_properties friction="0.0"/>
</joint>


<joint name="slide_right" type="prismatic">
<origin xyz="0.0074314381148364444529 0.015896861565316222631 -0.040325652756017238421" rpy="-1.5707963267948970021 1.5707963267948092945 0" />
<parent link="gripper_assembly_outer" />
<child link="right_jaw" />
<axis xyz="0 0 1"/>
<limit effort="12" velocity="20" lower="0.0" upper="0.015"/>
<joint_properties friction="0.0"/>
<mimic joint="slide_left"/>
</joint>
</robot>