<?xml version="1.0"?>
<robot name="arctos">
  <link name="arctos_base">
    <visual>
      <origin xyz="0 0 0" rpy="0 0 0" />
      <geometry>
        <mesh filename="arctos_base.stl" />
      </geometry>
      <material name="arctos_base_material">
        <color rgba="0.365 0.349 0.349 1.0" />
      </material>
    </visual>
    <collision>
      <origin xyz="0 0 0" rpy="0 0 0" />
      <geometry>
        <mesh filename="arctos_base.stl" />
      </geometry>
    </collision>
    <inertial>
      <origin xyz="-0.036191 0.000208 0.068366" rpy="0 0 0" />
      <mass value="1.041338" />
      <inertia ixx="0.004115" ixy="0.000010" ixz="-0.000245" iyy="0.008014" iyz="0.000020"
        izz="0.009152" />
    </inertial>
  </link>

  <link name="arctos_lower">
    <visual>
      <origin xyz="0 0 0" rpy="3.14159 0 0" />
      <geometry>
        <mesh filename="arctos_lower.stl" />
      </geometry>
      <material name="arctos_lower_material">
        <color rgba="0.365 0.349 0.349 1.0" />
      </material>
    </visual>
    <collision>
      <origin xyz="0 0 0" rpy="3.14159 0 0" />
      <geometry>
        <mesh filename="arctos_lower.stl" />
      </geometry>
    </collision>
    <inertial>
      <origin xyz="0.004745 -0.000758 -0.068543" rpy="0 0 0" />
      <mass value="1.411832" />
      <inertia ixx="0.009987" ixy="-0.000016" ixz="0.000568" iyy="0.008507" iyz="-0.000040"
        izz="0.007455" />
    </inertial>
  </link>

  <link name="arctos_middle">
    <visual>
      <origin xyz="0 0 0" rpy="1.5708 0 0" />
      <geometry>
        <mesh filename="arctos_middle.stl" />
      </geometry>
      <material name="arctos_middle_material">
        <color rgba="0.365 0.349 0.349 1.0" />
      </material>
    </visual>
    <collision>
      <origin xyz="0 0 0" rpy="1.5708 0 0" />
      <geometry>
        <mesh filename="arctos_middle.stl" />
      </geometry>
    </collision>
    <inertial>
      <origin xyz="-0.007761 -0.097207 -0.002104" rpy="0 0 0" />
      <mass value="1.572243" />
      <inertia ixx="0.021008" ixy="-0.000581" ixz="-0.000002" iyy="0.005410" iyz="-0.000355"
        izz="0.019428" />
    </inertial>
  </link>

  <link name="arctos_upper">
    <visual>
      <origin xyz="0 0 0" rpy="1.5708 0 0" />
      <geometry>
        <mesh filename="arctos_upper.stl" />
      </geometry>
      <material name="arctos_upper_material">
        <color rgba="0.365 0.349 0.349 1.0" />
      </material>
    </visual>
    <collision>
      <origin xyz="0 0 0" rpy="1.5708 0 0" />
      <geometry>
        <mesh filename="arctos_upper.stl" />
      </geometry>
    </collision>
    <inertial>
      <origin xyz="0.042604 -0.013186 -0.004432" rpy="0 0 0" />
      <mass value="0.627244" />
      <inertia ixx="0.001098" ixy="0.000344" ixz="0.000027" iyy="0.002304" iyz="0.000001"
        izz="0.002429" />
    </inertial>
  </link>

  <link name="wrist">
    <visual>
      <origin xyz="0 0 0" rpy="1.5708 1.5708 0" />
      <geometry>
        <mesh filename="wrist.stl" />
      </geometry>
      <material name="wrist_material">
        <color rgba="0.365 0.349 0.349 1.0" />
      </material>
    </visual>
    <collision>
      <origin xyz="0 0 0" rpy="1.5708 1.5708 0" />
      <geometry>
        <mesh filename="wrist.stl" />
      </geometry>
    </collision>
    <inertial>
      <origin xyz="0.000327 0.000886 -0.062634" rpy="0 0 0" />
      <mass value="0.567009" />
      <inertia ixx="0.001722" ixy="-0.000003" ixz="0.000002" iyy="0.002528" iyz="0.000004"
        izz="0.001648" />
    </inertial>
  </link>

  <link name="gripper_assembly_inner">
    <visual>
      <origin xyz="0.039835 0 0" rpy="1.5708 0 0" />
      <geometry>
        <mesh filename="gripper_assembly_inner.stl" />
      </geometry>
      <material name="gripper_assembly_inner_material">
        <color rgba="0.365 0.349 0.349 1.0" />
      </material>
    </visual>
    <collision>
      <origin xyz="0.039835 0 0" rpy="1.5708 0 0" />
      <geometry>
        <mesh filename="gripper_assembly_inner.stl" />
      </geometry>
    </collision>
    <inertial>
      <origin xyz="0.011021 0.000942 -0.000011" rpy="0 0 0" />
      <mass value="0.194632" />
      <inertia ixx="0.000191" ixy="-0.000003" ixz="0.000001" iyy="0.000181" iyz="-0.000001"
        izz="0.000137" />
    </inertial>
  </link>

  <link name="gripper_assembly_outer">
    <visual>
      <origin xyz="0 0 0" rpy="0 1.5708 0" />
      <geometry>
        <mesh filename="gripper_assembly_outer.stl" />
      </geometry>
      <material name="gripper_assembly_outer_material">
        <color rgba="0.365 0.349 0.349 1.0" />
      </material>
    </visual>
    <collision>
      <origin xyz="0 0 0" rpy="0 1.5708 0" />
      <geometry>
        <mesh filename="gripper_assembly_outer.stl" />
      </geometry>
    </collision>
    <inertial>
      <origin xyz="0.002248 0.001513 -0.015235" rpy="0 0 0" />
      <mass value="0.133828" />
      <inertia ixx="0.000075" ixy="-0.000000" ixz="0.000001" iyy="0.000054" iyz="0.000002"
        izz="0.000094" />
    </inertial>
  </link>

  <link name="left_jaw">
    <visual>
      <origin xyz="0 0 0" rpy="-1.5708 0 0" />
      <geometry>
        <mesh filename="left_jaw.stl" />
      </geometry>
      <material name="left_jaw_material">
        <color rgba="0.365 0.349 0.349 1.0" />
      </material>
    </visual>
    <collision>
      <origin xyz="0 0 0" rpy="-1.5708 0 0" />
      <geometry>
        <mesh filename="left_jaw.stl" />
      </geometry>
    </collision>
    <inertial>
      <origin xyz="0.009652 0.008564 -0.009362" rpy="0 0 0" />
      <mass value="0.010463" />
      <inertia ixx="0.000001" ixy="-0.000000" ixz="0.000000" iyy="0.000002" iyz="-0.000000"
        izz="0.000002" />
    </inertial>
  </link>

  <link name="right_jaw">
    <visual>
      <origin xyz="0 0 0" rpy="-1.5708 0 0" />
      <geometry>
        <mesh filename="right_jaw.stl" />
      </geometry>
      <material name="right_jaw_material">
        <color rgba="0.365 0.349 0.349 1.0" />
      </material>
    </visual>
    <collision>
      <origin xyz="0 0 0" rpy="-1.5708 0 0" />
      <geometry>
        <mesh filename="right_jaw.stl" />
      </geometry>
    </collision>
    <inertial>
      <origin xyz="0.009878 0.008398 -0.009370" rpy="0 0 0" />
      <mass value="0.010168" />
      <inertia ixx="0.000001" ixy="-0.000000" ixz="0.000000" iyy="0.000002" iyz="-0.000000"
        izz="0.000002" />
    </inertial>
  </link>

  <joint name="slide_left" type="prismatic">
    <origin xyz="0.007431 0.030780 -0.040326" rpy="-1.5708 1.5708 0" />
    <parent link="gripper_assembly_outer" />
    <child link="left_jaw" />
    <axis xyz="0 0 1" />
    <limit effort="70" velocity="40" lower="-0.015" upper="0" />
    <joint_properties friction="0.0" />
  </joint>

  <joint name="slide_right" type="prismatic">
    <origin xyz="-0.012068 -0.028986 -0.040244" rpy="1.5708 1.5708 0" />
    <parent link="gripper_assembly_outer" />
    <child link="right_jaw" />
    <axis xyz="0 0 1" />
    <limit effort="70" velocity="40" lower="-0.015" upper="0" />
    <joint_properties friction="0.0" />
  </joint>

  <joint name="outer_inner" type="revolute">
    <origin xyz="0.039835 0 0" rpy="1.5708 0 -1.5708" />
    <parent link="gripper_assembly_inner" />
    <child link="gripper_assembly_outer" />
    <axis xyz="0 0 1" />
    <limit effort="70" velocity="40" lower="-4.71239" upper="4.71239" />
    <joint_properties friction="0.0" />
  </joint>

  <joint name="inner_wrist" type="revolute">
    <origin xyz="0.000219 0.001774 -0.125424" rpy="0 1.5708 0" />
    <parent link="wrist" />
    <child link="gripper_assembly_inner" />
    <axis xyz="0 0 1" />
    <!-- <limit effort="70" velocity="40" lower="-1.74533" upper="1.74533"/> -->
    <limit effort="70" velocity="40" lower="1.22173" upper="4.71239" />
    <joint_properties friction="0.0" />
  </joint>

  <joint name="wrist_upper" type="revolute">
    <origin xyz="0.138743 -0.021749 -0.005493" rpy="-0.001990 -1.5708 0" />
    <parent link="arctos_upper" />
    <child link="wrist" />
    <axis xyz="0 0 1" />
    <limit effort="70" velocity="40" lower="-4.71239" upper="4.71239" />
    <joint_properties friction="0.0" />
  </joint>

  <joint name="upper_middle" type="revolute">
    <origin xyz="-0.001310 -0.261007 0.005429" rpy="0 0 0" />
    <parent link="arctos_middle" />
    <child link="arctos_upper" />
    <axis xyz="0 0 1" />
    <limit effort="70" velocity="40" lower="-1.91986" upper="0.87266" />
    <joint_properties friction="0.0" />
  </joint>

  <joint name="middle_lower" type="revolute">
    <origin xyz="0.020885 0.000870 -0.157722" rpy="1.5708 0 0" />
    <parent link="arctos_lower" />
    <child link="arctos_middle" />
    <axis xyz="0 0 1" />
    <limit effort="70" velocity="40" lower="-1.22173" upper="2.18166" />
    <joint_properties friction="0.0" />
  </joint>

  <joint name="lower_base" type="revolute">
    <origin xyz="-0.000529 0 0.129906" rpy="-3.14159 0 0.004351" />
    <parent link="arctos_base" />
    <child link="arctos_lower" />
    <axis xyz="0 0 1" />
    <limit effort="70" velocity="40" lower="-4.71239" upper="4.71239" />
    <joint_properties friction="0.0" />
  </joint>


</robot>